Traceback (most recent call last):
  File "/opt/hostedtoolcache/Python/3.10.10/x64/lib/python3.10/site-packages/jupyter_cache/executors/utils.py", line 58, in single_nb_execution
    executenb(
  File "/opt/hostedtoolcache/Python/3.10.10/x64/lib/python3.10/site-packages/nbclient/client.py", line 1204, in execute
    return NotebookClient(nb=nb, resources=resources, km=km, **kwargs).execute()
  File "/opt/hostedtoolcache/Python/3.10.10/x64/lib/python3.10/site-packages/nbclient/util.py", line 84, in wrapped
    return just_run(coro(*args, **kwargs))
  File "/opt/hostedtoolcache/Python/3.10.10/x64/lib/python3.10/site-packages/nbclient/util.py", line 62, in just_run
    return loop.run_until_complete(coro)
  File "/opt/hostedtoolcache/Python/3.10.10/x64/lib/python3.10/asyncio/base_events.py", line 649, in run_until_complete
    return future.result()
  File "/opt/hostedtoolcache/Python/3.10.10/x64/lib/python3.10/site-packages/nbclient/client.py", line 663, in async_execute
    await self.async_execute_cell(
  File "/opt/hostedtoolcache/Python/3.10.10/x64/lib/python3.10/site-packages/nbclient/client.py", line 965, in async_execute_cell
    await self._check_raise_for_error(cell, cell_index, exec_reply)
  File "/opt/hostedtoolcache/Python/3.10.10/x64/lib/python3.10/site-packages/nbclient/client.py", line 862, in _check_raise_for_error
    raise CellExecutionError.from_cell_and_msg(cell, exec_reply_content)
nbclient.exceptions.CellExecutionError: An error occurred while executing the following cell:
------------------
def my_function(x):
 if x < 0:
  raise MyCustomException("Input must be non-negative")
 else:
  return x ** 2

try:
 result = my_function(-1)
except MyCustomException as e:
 print(e)
------------------

[0;31m---------------------------------------------------------------------------[0m
[0;31mNameError[0m                                 Traceback (most recent call last)
Cell [0;32mIn[3], line 8[0m
[1;32m      7[0m [38;5;28;01mtry[39;00m:
[0;32m----> 8[0m  result [38;5;241m=[39m [43mmy_function[49m[43m([49m[38;5;241;43m-[39;49m[38;5;241;43m1[39;49m[43m)[49m
[1;32m      9[0m [38;5;28;01mexcept[39;00m MyCustomException [38;5;28;01mas[39;00m e:

Cell [0;32mIn[3], line 3[0m, in [0;36mmy_function[0;34m(x)[0m
[1;32m      2[0m [38;5;28;01mif[39;00m x [38;5;241m<[39m [38;5;241m0[39m:
[0;32m----> 3[0m  [38;5;28;01mraise[39;00m [43mMyCustomException[49m([38;5;124m"[39m[38;5;124mInput must be non-negative[39m[38;5;124m"[39m)
[1;32m      4[0m [38;5;28;01melse[39;00m:

[0;31mNameError[0m: name 'MyCustomException' is not defined

During handling of the above exception, another exception occurred:

[0;31mNameError[0m                                 Traceback (most recent call last)
Cell [0;32mIn[3], line 9[0m
[1;32m      7[0m [38;5;28;01mtry[39;00m:
[1;32m      8[0m  result [38;5;241m=[39m my_function([38;5;241m-[39m[38;5;241m1[39m)
[0;32m----> 9[0m [38;5;28;01mexcept[39;00m [43mMyCustomException[49m [38;5;28;01mas[39;00m e:
[1;32m     10[0m  [38;5;28mprint[39m(e)

[0;31mNameError[0m: name 'MyCustomException' is not defined
NameError: name 'MyCustomException' is not defined

